ERROR 2025-05-06 19:36:23,505 log Internal Server Error: /accounts/register/
Traceback (most recent call last):
  File "/usr/local/lib/python3.10/site-packages/django/core/handlers/exception.py", line 55, in inner
    response = get_response(request)
  File "/usr/local/lib/python3.10/site-packages/django/core/handlers/base.py", line 197, in _get_response
    response = wrapped_callback(request, *callback_args, **callback_kwargs)
  File "/app/apps/accounts/views.py", line 64, in register_view
    send_mail(
  File "/usr/local/lib/python3.10/site-packages/django/core/mail/__init__.py", line 87, in send_mail
    return mail.send()
  File "/usr/local/lib/python3.10/site-packages/django/core/mail/message.py", line 298, in send
    return self.get_connection(fail_silently).send_messages([self])
  File "/usr/local/lib/python3.10/site-packages/django/core/mail/backends/smtp.py", line 127, in send_messages
    new_conn_created = self.open()
  File "/usr/local/lib/python3.10/site-packages/django/core/mail/backends/smtp.py", line 85, in open
    self.connection = self.connection_class(
  File "/usr/local/lib/python3.10/smtplib.py", line 255, in __init__
    (code, msg) = self.connect(host, port)
  File "/usr/local/lib/python3.10/smtplib.py", line 341, in connect
    self.sock = self._get_socket(host, port, self.timeout)
  File "/usr/local/lib/python3.10/smtplib.py", line 312, in _get_socket
    return socket.create_connection((host, port), timeout,
  File "/usr/local/lib/python3.10/socket.py", line 857, in create_connection
    raise err
  File "/usr/local/lib/python3.10/socket.py", line 845, in create_connection
    sock.connect(sa)
ConnectionRefusedError: [Errno 111] Connection refused
ERROR 2025-05-06 19:36:23,512 basehttp "POST /accounts/register/ HTTP/1.0" 500 108199
