ERROR 2025-05-06 19:36:23,505 log Internal Server Error: /accounts/register/
Traceback (most recent call last):
  File "/usr/local/lib/python3.10/site-packages/django/core/handlers/exception.py", line 55, in inner
    response = get_response(request)
  File "/usr/local/lib/python3.10/site-packages/django/core/handlers/base.py", line 197, in _get_response
    response = wrapped_callback(request, *callback_args, **callback_kwargs)
  File "/app/apps/accounts/views.py", line 64, in register_view
    send_mail(
  File "/usr/local/lib/python3.10/site-packages/django/core/mail/__init__.py", line 87, in send_mail
    return mail.send()
  File "/usr/local/lib/python3.10/site-packages/django/core/mail/message.py", line 298, in send
    return self.get_connection(fail_silently).send_messages([self])
  File "/usr/local/lib/python3.10/site-packages/django/core/mail/backends/smtp.py", line 127, in send_messages
    new_conn_created = self.open()
  File "/usr/local/lib/python3.10/site-packages/django/core/mail/backends/smtp.py", line 85, in open
    self.connection = self.connection_class(
  File "/usr/local/lib/python3.10/smtplib.py", line 255, in __init__
    (code, msg) = self.connect(host, port)
  File "/usr/local/lib/python3.10/smtplib.py", line 341, in connect
    self.sock = self._get_socket(host, port, self.timeout)
  File "/usr/local/lib/python3.10/smtplib.py", line 312, in _get_socket
    return socket.create_connection((host, port), timeout,
  File "/usr/local/lib/python3.10/socket.py", line 857, in create_connection
    raise err
  File "/usr/local/lib/python3.10/socket.py", line 845, in create_connection
    sock.connect(sa)
ConnectionRefusedError: [Errno 111] Connection refused
ERROR 2025-05-06 19:36:23,512 basehttp "POST /accounts/register/ HTTP/1.0" 500 108199
ERROR 2025-05-06 19:46:48,359 log Internal Server Error: /accounts/verify-email/Pb5lVrtl7x5fOamKoLMqswDwfwhZHvzOk4HFEp95r2j20nDqsJFITQ5aKWEevP6Y/
Traceback (most recent call last):
  File "/app/apps/accounts/views.py", line 85, in verify_email
    profile = Profile.objects.get(email_verification_token=token)
NameError: name 'Profile' is not defined

During handling of the above exception, another exception occurred:

Traceback (most recent call last):
  File "/usr/local/lib/python3.10/site-packages/django/core/handlers/exception.py", line 55, in inner
    response = get_response(request)
  File "/usr/local/lib/python3.10/site-packages/django/core/handlers/base.py", line 197, in _get_response
    response = wrapped_callback(request, *callback_args, **callback_kwargs)
  File "/app/apps/accounts/views.py", line 104, in verify_email
    except Profile.DoesNotExist:
NameError: name 'Profile' is not defined
ERROR 2025-05-06 19:46:48,370 basehttp "GET /accounts/verify-email/Pb5lVrtl7x5fOamKoLMqswDwfwhZHvzOk4HFEp95r2j20nDqsJFITQ5aKWEevP6Y/ HTTP/1.0" 500 68786
ERROR 2025-05-06 19:49:24,866 log Internal Server Error: /accounts/verify-email/Pb5lVrtl7x5fOamKoLMqswDwfwhZHvzOk4HFEp95r2j20nDqsJFITQ5aKWEevP6Y/
Traceback (most recent call last):
  File "/usr/local/lib/python3.10/site-packages/django/core/handlers/exception.py", line 55, in inner
    response = get_response(request)
  File "/usr/local/lib/python3.10/site-packages/django/core/handlers/base.py", line 197, in _get_response
    response = wrapped_callback(request, *callback_args, **callback_kwargs)
  File "/app/apps/accounts/views.py", line 100, in verify_email
    if timezone.now() - timezone.make_aware(sent_time) > timedelta(hours=24):
  File "/usr/local/lib/python3.10/site-packages/django/utils/timezone.py", line 291, in make_aware
    raise ValueError("make_aware expects a naive datetime, got %s" % value)
ValueError: make_aware expects a naive datetime, got 2025-05-06 14:45:47.550366+00:00
ERROR 2025-05-06 19:49:24,884 basehttp "GET /accounts/verify-email/Pb5lVrtl7x5fOamKoLMqswDwfwhZHvzOk4HFEp95r2j20nDqsJFITQ5aKWEevP6Y/ HTTP/1.0" 500 70202
ERROR 2025-05-06 19:52:03,250 log Internal Server Error: /accounts/verify-email/w9Ivwdbj2TXIcf0dbNyIrTDjt08QRhwLnBxkM9qz1KgTNz0wL0pdP7TaBQRywBt0/
Traceback (most recent call last):
  File "/usr/local/lib/python3.10/site-packages/django/core/handlers/exception.py", line 55, in inner
    response = get_response(request)
  File "/usr/local/lib/python3.10/site-packages/django/core/handlers/base.py", line 197, in _get_response
    response = wrapped_callback(request, *callback_args, **callback_kwargs)
  File "/app/apps/accounts/views.py", line 100, in verify_email
    if timezone.now() - timezone.make_aware(sent_time) > timedelta(hours=24):
  File "/usr/local/lib/python3.10/site-packages/django/utils/timezone.py", line 291, in make_aware
    raise ValueError("make_aware expects a naive datetime, got %s" % value)
ValueError: make_aware expects a naive datetime, got 2025-05-06 14:51:53.238941+00:00
ERROR 2025-05-06 19:52:03,260 basehttp "GET /accounts/verify-email/w9Ivwdbj2TXIcf0dbNyIrTDjt08QRhwLnBxkM9qz1KgTNz0wL0pdP7TaBQRywBt0/ HTTP/1.0" 500 70201
ERROR 2025-05-06 19:55:32,743 log Internal Server Error: /orders/my-orders/
Traceback (most recent call last):
  File "/usr/local/lib/python3.10/site-packages/django/core/handlers/exception.py", line 55, in inner
    response = get_response(request)
  File "/usr/local/lib/python3.10/site-packages/django/core/handlers/base.py", line 197, in _get_response
    response = wrapped_callback(request, *callback_args, **callback_kwargs)
  File "/usr/local/lib/python3.10/site-packages/django/contrib/auth/decorators.py", line 23, in _wrapper_view
    return view_func(request, *args, **kwargs)
  File "/app/apps/orders/views.py", line 154, in my_orders
    return render(request, 'orders/my_orders.html', {'orders': orders})
  File "/usr/local/lib/python3.10/site-packages/django/shortcuts.py", line 24, in render
    content = loader.render_to_string(template_name, context, request, using=using)
  File "/usr/local/lib/python3.10/site-packages/django/template/loader.py", line 61, in render_to_string
    template = get_template(template_name, using=using)
  File "/usr/local/lib/python3.10/site-packages/django/template/loader.py", line 19, in get_template
    raise TemplateDoesNotExist(template_name, chain=chain)
django.template.exceptions.TemplateDoesNotExist: orders/my_orders.html
ERROR 2025-05-06 19:55:32,762 basehttp "GET /orders/my-orders/ HTTP/1.0" 500 84401
ERROR 2025-05-06 19:57:20,360 log Internal Server Error: /accounts/profile/addresses/
Traceback (most recent call last):
  File "/usr/local/lib/python3.10/site-packages/django/core/handlers/exception.py", line 55, in inner
    response = get_response(request)
  File "/usr/local/lib/python3.10/site-packages/django/core/handlers/base.py", line 197, in _get_response
    response = wrapped_callback(request, *callback_args, **callback_kwargs)
  File "/usr/local/lib/python3.10/site-packages/django/contrib/auth/decorators.py", line 23, in _wrapper_view
    return view_func(request, *args, **kwargs)
  File "/app/apps/accounts/views.py", line 289, in address_list
    return render(request, 'accounts/address_list.html', {'addresses': addresses})
  File "/usr/local/lib/python3.10/site-packages/django/shortcuts.py", line 24, in render
    content = loader.render_to_string(template_name, context, request, using=using)
  File "/usr/local/lib/python3.10/site-packages/django/template/loader.py", line 61, in render_to_string
    template = get_template(template_name, using=using)
  File "/usr/local/lib/python3.10/site-packages/django/template/loader.py", line 19, in get_template
    raise TemplateDoesNotExist(template_name, chain=chain)
django.template.exceptions.TemplateDoesNotExist: accounts/address_list.html
ERROR 2025-05-06 19:57:20,371 basehttp "GET /accounts/profile/addresses/ HTTP/1.0" 500 84285
ERROR 2025-05-06 19:58:16,330 log Internal Server Error: /wishlist/
Traceback (most recent call last):
  File "/usr/local/lib/python3.10/site-packages/django/core/handlers/exception.py", line 55, in inner
    response = get_response(request)
  File "/usr/local/lib/python3.10/site-packages/django/core/handlers/base.py", line 197, in _get_response
    response = wrapped_callback(request, *callback_args, **callback_kwargs)
  File "/usr/local/lib/python3.10/site-packages/django/contrib/auth/decorators.py", line 23, in _wrapper_view
    return view_func(request, *args, **kwargs)
  File "/app/apps/products/views.py", line 239, in wishlist
    return render(request, 'products/wishlist.html', context)
  File "/usr/local/lib/python3.10/site-packages/django/shortcuts.py", line 24, in render
    content = loader.render_to_string(template_name, context, request, using=using)
  File "/usr/local/lib/python3.10/site-packages/django/template/loader.py", line 61, in render_to_string
    template = get_template(template_name, using=using)
  File "/usr/local/lib/python3.10/site-packages/django/template/loader.py", line 19, in get_template
    raise TemplateDoesNotExist(template_name, chain=chain)
django.template.exceptions.TemplateDoesNotExist: products/wishlist.html
ERROR 2025-05-06 19:58:16,343 basehttp "GET /wishlist/ HTTP/1.0" 500 84402
ERROR 2025-05-06 19:59:26,325 log Internal Server Error: /notifications/
Traceback (most recent call last):
  File "/usr/local/lib/python3.10/site-packages/django/core/handlers/exception.py", line 55, in inner
    response = get_response(request)
  File "/usr/local/lib/python3.10/site-packages/django/core/handlers/base.py", line 197, in _get_response
    response = wrapped_callback(request, *callback_args, **callback_kwargs)
  File "/usr/local/lib/python3.10/site-packages/django/contrib/auth/decorators.py", line 23, in _wrapper_view
    return view_func(request, *args, **kwargs)
  File "/app/apps/notifications/views.py", line 14, in notification_list
    return render(request, 'notifications/notification_list.html', {
  File "/usr/local/lib/python3.10/site-packages/django/shortcuts.py", line 24, in render
    content = loader.render_to_string(template_name, context, request, using=using)
  File "/usr/local/lib/python3.10/site-packages/django/template/loader.py", line 61, in render_to_string
    template = get_template(template_name, using=using)
  File "/usr/local/lib/python3.10/site-packages/django/template/loader.py", line 19, in get_template
    raise TemplateDoesNotExist(template_name, chain=chain)
django.template.exceptions.TemplateDoesNotExist: notifications/notification_list.html
ERROR 2025-05-06 19:59:26,337 basehttp "GET /notifications/ HTTP/1.0" 500 84536
ERROR 2025-05-06 20:00:38,054 log Internal Server Error: /notifications/settings/
Traceback (most recent call last):
  File "/usr/local/lib/python3.10/site-packages/django/core/handlers/exception.py", line 55, in inner
    response = get_response(request)
  File "/usr/local/lib/python3.10/site-packages/django/core/handlers/base.py", line 197, in _get_response
    response = wrapped_callback(request, *callback_args, **callback_kwargs)
  File "/usr/local/lib/python3.10/site-packages/django/contrib/auth/decorators.py", line 23, in _wrapper_view
    return view_func(request, *args, **kwargs)
  File "/app/apps/notifications/views.py", line 66, in notification_settings
    return render(request, 'notifications/notification_settings.html', {'form': form})
  File "/usr/local/lib/python3.10/site-packages/django/shortcuts.py", line 24, in render
    content = loader.render_to_string(template_name, context, request, using=using)
  File "/usr/local/lib/python3.10/site-packages/django/template/loader.py", line 61, in render_to_string
    template = get_template(template_name, using=using)
  File "/usr/local/lib/python3.10/site-packages/django/template/loader.py", line 19, in get_template
    raise TemplateDoesNotExist(template_name, chain=chain)
django.template.exceptions.TemplateDoesNotExist: notifications/notification_settings.html
ERROR 2025-05-06 20:00:38,062 basehttp "GET /notifications/settings/ HTTP/1.0" 500 84323
ERROR 2025-05-06 20:02:53,618 log Internal Server Error: /accounts/profile/edit/
Traceback (most recent call last):
  File "/usr/local/lib/python3.10/site-packages/django/core/handlers/exception.py", line 55, in inner
    response = get_response(request)
  File "/usr/local/lib/python3.10/site-packages/django/core/handlers/base.py", line 197, in _get_response
    response = wrapped_callback(request, *callback_args, **callback_kwargs)
  File "/usr/local/lib/python3.10/site-packages/django/contrib/auth/decorators.py", line 23, in _wrapper_view
    return view_func(request, *args, **kwargs)
  File "/app/apps/accounts/views.py", line 270, in edit_profile
    return render(request, 'accounts/edit_profile.html', {'form': form})
  File "/usr/local/lib/python3.10/site-packages/django/shortcuts.py", line 24, in render
    content = loader.render_to_string(template_name, context, request, using=using)
  File "/usr/local/lib/python3.10/site-packages/django/template/loader.py", line 61, in render_to_string
    template = get_template(template_name, using=using)
  File "/usr/local/lib/python3.10/site-packages/django/template/loader.py", line 19, in get_template
    raise TemplateDoesNotExist(template_name, chain=chain)
django.template.exceptions.TemplateDoesNotExist: accounts/edit_profile.html
ERROR 2025-05-06 20:02:53,625 basehttp "GET /accounts/profile/edit/ HTTP/1.0" 500 84488
ERROR 2025-05-06 20:03:54,944 log Internal Server Error: /accounts/profile/change-password/
Traceback (most recent call last):
  File "/usr/local/lib/python3.10/site-packages/django/core/handlers/exception.py", line 55, in inner
    response = get_response(request)
  File "/usr/local/lib/python3.10/site-packages/django/core/handlers/base.py", line 197, in _get_response
    response = wrapped_callback(request, *callback_args, **callback_kwargs)
  File "/usr/local/lib/python3.10/site-packages/django/contrib/auth/decorators.py", line 23, in _wrapper_view
    return view_func(request, *args, **kwargs)
  File "/app/apps/accounts/views.py", line 284, in change_password
    return render(request, 'accounts/change_password.html', {'form': form})
  File "/usr/local/lib/python3.10/site-packages/django/shortcuts.py", line 24, in render
    content = loader.render_to_string(template_name, context, request, using=using)
  File "/usr/local/lib/python3.10/site-packages/django/template/loader.py", line 61, in render_to_string
    template = get_template(template_name, using=using)
  File "/usr/local/lib/python3.10/site-packages/django/template/loader.py", line 19, in get_template
    raise TemplateDoesNotExist(template_name, chain=chain)
django.template.exceptions.TemplateDoesNotExist: accounts/change_password.html
ERROR 2025-05-06 20:03:54,952 basehttp "GET /accounts/profile/change-password/ HTTP/1.0" 500 84818
ERROR 2025-05-06 20:05:48,052 log Internal Server Error: /cart/
Traceback (most recent call last):
  File "/usr/local/lib/python3.10/site-packages/django/core/handlers/exception.py", line 55, in inner
    response = get_response(request)
  File "/usr/local/lib/python3.10/site-packages/django/core/handlers/base.py", line 197, in _get_response
    response = wrapped_callback(request, *callback_args, **callback_kwargs)
  File "/usr/local/lib/python3.10/site-packages/django/contrib/auth/decorators.py", line 23, in _wrapper_view
    return view_func(request, *args, **kwargs)
  File "/app/apps/products/views.py", line 166, in cart
    return render(request, 'products/cart.html', context)
  File "/usr/local/lib/python3.10/site-packages/django/shortcuts.py", line 24, in render
    content = loader.render_to_string(template_name, context, request, using=using)
  File "/usr/local/lib/python3.10/site-packages/django/template/loader.py", line 61, in render_to_string
    template = get_template(template_name, using=using)
  File "/usr/local/lib/python3.10/site-packages/django/template/loader.py", line 19, in get_template
    raise TemplateDoesNotExist(template_name, chain=chain)
django.template.exceptions.TemplateDoesNotExist: products/cart.html
ERROR 2025-05-06 20:05:48,062 basehttp "GET /cart/ HTTP/1.0" 500 84123
WARNING 2025-05-06 20:54:06,297 log Not Found: /.well-known/appspecific/com.chrome.devtools.json
WARNING 2025-05-06 20:54:06,300 basehttp "GET /.well-known/appspecific/com.chrome.devtools.json HTTP/1.0" 404 7320
WARNING 2025-05-06 20:54:07,058 log Not Found: /.well-known/appspecific/com.chrome.devtools.json
WARNING 2025-05-06 20:54:07,060 basehttp "GET /.well-known/appspecific/com.chrome.devtools.json HTTP/1.0" 404 7320
WARNING 2025-05-06 20:56:43,142 log Not Found: /login
WARNING 2025-05-06 20:56:43,144 basehttp "GET /login HTTP/1.0" 404 7191
ERROR 2025-05-06 20:57:11,813 log Internal Server Error: /seller/orders/
Traceback (most recent call last):
  File "/usr/local/lib/python3.10/site-packages/django/core/handlers/exception.py", line 55, in inner
    response = get_response(request)
  File "/usr/local/lib/python3.10/site-packages/django/core/handlers/base.py", line 220, in _get_response
    response = response.render()
  File "/usr/local/lib/python3.10/site-packages/django/template/response.py", line 114, in render
    self.content = self.rendered_content
  File "/usr/local/lib/python3.10/site-packages/django/template/response.py", line 90, in rendered_content
    template = self.resolve_template(self.template_name)
  File "/usr/local/lib/python3.10/site-packages/django/template/response.py", line 72, in resolve_template
    return select_template(template, using=self.using)
  File "/usr/local/lib/python3.10/site-packages/django/template/loader.py", line 47, in select_template
    raise TemplateDoesNotExist(", ".join(template_name_list), chain=chain)
django.template.exceptions.TemplateDoesNotExist: orders/seller_orders.html, orders/order_list.html
ERROR 2025-05-06 20:57:11,819 basehttp "GET /seller/orders/ HTTP/1.0" 500 80758
ERROR 2025-05-06 20:59:00,209 log Internal Server Error: /chat/
Traceback (most recent call last):
  File "/usr/local/lib/python3.10/site-packages/django/core/handlers/exception.py", line 55, in inner
    response = get_response(request)
  File "/usr/local/lib/python3.10/site-packages/django/core/handlers/base.py", line 197, in _get_response
    response = wrapped_callback(request, *callback_args, **callback_kwargs)
  File "/usr/local/lib/python3.10/site-packages/django/contrib/auth/decorators.py", line 23, in _wrapper_view
    return view_func(request, *args, **kwargs)
  File "/app/apps/chat/views.py", line 20, in chat_list
    return render(request, 'chat/chat_list.html', {'conversations': conversations})
  File "/usr/local/lib/python3.10/site-packages/django/shortcuts.py", line 24, in render
    content = loader.render_to_string(template_name, context, request, using=using)
  File "/usr/local/lib/python3.10/site-packages/django/template/loader.py", line 61, in render_to_string
    template = get_template(template_name, using=using)
  File "/usr/local/lib/python3.10/site-packages/django/template/loader.py", line 19, in get_template
    raise TemplateDoesNotExist(template_name, chain=chain)
django.template.exceptions.TemplateDoesNotExist: chat/chat_list.html
ERROR 2025-05-06 20:59:00,223 basehttp "GET /chat/ HTTP/1.0" 500 84014
ERROR 2025-05-06 21:30:22,688 log Internal Server Error: /seller/product/add/
Traceback (most recent call last):
  File "/usr/local/lib/python3.10/site-packages/django/core/handlers/exception.py", line 55, in inner
    response = get_response(request)
  File "/usr/local/lib/python3.10/site-packages/django/core/handlers/base.py", line 197, in _get_response
    response = wrapped_callback(request, *callback_args, **callback_kwargs)
  File "/usr/local/lib/python3.10/site-packages/django/views/generic/base.py", line 104, in view
    return self.dispatch(request, *args, **kwargs)
  File "/usr/local/lib/python3.10/site-packages/django/contrib/auth/mixins.py", line 73, in dispatch
    return super().dispatch(request, *args, **kwargs)
  File "/app/apps/products/views.py", line 314, in dispatch
    return super().dispatch(request, *args, **kwargs)
  File "/usr/local/lib/python3.10/site-packages/django/views/generic/base.py", line 143, in dispatch
    return handler(request, *args, **kwargs)
  File "/usr/local/lib/python3.10/site-packages/django/views/generic/edit.py", line 180, in get
    return super().get(request, *args, **kwargs)
  File "/usr/local/lib/python3.10/site-packages/django/views/generic/edit.py", line 144, in get
    return self.render_to_response(self.get_context_data())
  File "/app/apps/products/views.py", line 421, in get_context_data
    context['attribute_formset'] = ProductAttributeFormSet()
  File "/usr/local/lib/python3.10/site-packages/django/forms/models.py", line 1100, in __init__
    if self.form._meta.fields and self.fk.name not in self.form._meta.fields:
AttributeError: type object 'ProductAttributeForm' has no attribute '_meta'
ERROR 2025-05-06 21:30:22,701 basehttp "GET /seller/product/add/ HTTP/1.0" 500 97672
ERROR 2025-05-06 21:35:39,922 log Internal Server Error: /seller/product/add/
Traceback (most recent call last):
  File "/usr/local/lib/python3.10/site-packages/django/core/handlers/exception.py", line 55, in inner
    response = get_response(request)
  File "/usr/local/lib/python3.10/site-packages/django/core/handlers/base.py", line 197, in _get_response
    response = wrapped_callback(request, *callback_args, **callback_kwargs)
  File "/usr/local/lib/python3.10/site-packages/django/views/generic/base.py", line 104, in view
    return self.dispatch(request, *args, **kwargs)
  File "/usr/local/lib/python3.10/site-packages/django/contrib/auth/mixins.py", line 73, in dispatch
    return super().dispatch(request, *args, **kwargs)
  File "/app/apps/products/views.py", line 314, in dispatch
    return super().dispatch(request, *args, **kwargs)
  File "/usr/local/lib/python3.10/site-packages/django/views/generic/base.py", line 143, in dispatch
    return handler(request, *args, **kwargs)
  File "/usr/local/lib/python3.10/site-packages/django/views/generic/edit.py", line 184, in post
    return super().post(request, *args, **kwargs)
  File "/usr/local/lib/python3.10/site-packages/django/views/generic/edit.py", line 153, in post
    return self.form_valid(form)
  File "/app/apps/products/views.py", line 431, in form_valid
    ProductAttribute.objects.create(
NameError: name 'ProductAttribute' is not defined
ERROR 2025-05-06 21:35:39,932 basehttp "POST /seller/product/add/ HTTP/1.0" 500 94145
ERROR 2025-05-06 21:36:49,301 log Internal Server Error: /
Traceback (most recent call last):
  File "/usr/local/lib/python3.10/site-packages/django/core/handlers/exception.py", line 55, in inner
    response = get_response(request)
  File "/usr/local/lib/python3.10/site-packages/django/core/handlers/base.py", line 197, in _get_response
    response = wrapped_callback(request, *callback_args, **callback_kwargs)
  File "/app/apps/products/views.py", line 33, in home
    return render(request, 'products/home.html', context)
  File "/usr/local/lib/python3.10/site-packages/django/shortcuts.py", line 24, in render
    content = loader.render_to_string(template_name, context, request, using=using)
  File "/usr/local/lib/python3.10/site-packages/django/template/loader.py", line 62, in render_to_string
    return template.render(context, request)
  File "/usr/local/lib/python3.10/site-packages/django/template/backends/django.py", line 61, in render
    return self.template.render(context)
  File "/usr/local/lib/python3.10/site-packages/django/template/base.py", line 175, in render
    return self._render(context)
  File "/usr/local/lib/python3.10/site-packages/django/template/base.py", line 167, in _render
    return self.nodelist.render(context)
  File "/usr/local/lib/python3.10/site-packages/django/template/base.py", line 1005, in render
    return SafeString("".join([node.render_annotated(context) for node in self]))
  File "/usr/local/lib/python3.10/site-packages/django/template/base.py", line 1005, in <listcomp>
    return SafeString("".join([node.render_annotated(context) for node in self]))
  File "/usr/local/lib/python3.10/site-packages/django/template/base.py", line 966, in render_annotated
    return self.render(context)
  File "/usr/local/lib/python3.10/site-packages/django/template/loader_tags.py", line 157, in render
    return compiled_parent._render(context)
  File "/usr/local/lib/python3.10/site-packages/django/template/base.py", line 167, in _render
    return self.nodelist.render(context)
  File "/usr/local/lib/python3.10/site-packages/django/template/base.py", line 1005, in render
    return SafeString("".join([node.render_annotated(context) for node in self]))
  File "/usr/local/lib/python3.10/site-packages/django/template/base.py", line 1005, in <listcomp>
    return SafeString("".join([node.render_annotated(context) for node in self]))
  File "/usr/local/lib/python3.10/site-packages/django/template/base.py", line 966, in render_annotated
    return self.render(context)
  File "/usr/local/lib/python3.10/site-packages/django/template/loader_tags.py", line 63, in render
    result = block.nodelist.render(context)
  File "/usr/local/lib/python3.10/site-packages/django/template/base.py", line 1005, in render
    return SafeString("".join([node.render_annotated(context) for node in self]))
  File "/usr/local/lib/python3.10/site-packages/django/template/base.py", line 1005, in <listcomp>
    return SafeString("".join([node.render_annotated(context) for node in self]))
  File "/usr/local/lib/python3.10/site-packages/django/template/base.py", line 966, in render_annotated
    return self.render(context)
  File "/usr/local/lib/python3.10/site-packages/django/template/defaulttags.py", line 238, in render
    nodelist.append(node.render_annotated(context))
  File "/usr/local/lib/python3.10/site-packages/django/template/base.py", line 966, in render_annotated
    return self.render(context)
  File "/usr/local/lib/python3.10/site-packages/django/template/defaulttags.py", line 471, in render
    url = reverse(view_name, args=args, kwargs=kwargs, current_app=current_app)
  File "/usr/local/lib/python3.10/site-packages/django/urls/base.py", line 88, in reverse
    return resolver._reverse_with_prefix(view, prefix, *args, **kwargs)
  File "/usr/local/lib/python3.10/site-packages/django/urls/resolvers.py", line 828, in _reverse_with_prefix
    raise NoReverseMatch(msg)
django.urls.exceptions.NoReverseMatch: Reverse for 'product_detail' with arguments '('',)' not found. 1 pattern(s) tried: ['product/(?P<slug>[-a-zA-Z0-9_]+)/\\Z']
ERROR 2025-05-06 21:36:49,316 basehttp "GET / HTTP/1.0" 500 185301
ERROR 2025-05-06 21:37:00,477 log Internal Server Error: /
Traceback (most recent call last):
  File "/usr/local/lib/python3.10/site-packages/django/core/handlers/exception.py", line 55, in inner
    response = get_response(request)
  File "/usr/local/lib/python3.10/site-packages/django/core/handlers/base.py", line 197, in _get_response
    response = wrapped_callback(request, *callback_args, **callback_kwargs)
  File "/app/apps/products/views.py", line 33, in home
    return render(request, 'products/home.html', context)
  File "/usr/local/lib/python3.10/site-packages/django/shortcuts.py", line 24, in render
    content = loader.render_to_string(template_name, context, request, using=using)
  File "/usr/local/lib/python3.10/site-packages/django/template/loader.py", line 62, in render_to_string
    return template.render(context, request)
  File "/usr/local/lib/python3.10/site-packages/django/template/backends/django.py", line 61, in render
    return self.template.render(context)
  File "/usr/local/lib/python3.10/site-packages/django/template/base.py", line 175, in render
    return self._render(context)
  File "/usr/local/lib/python3.10/site-packages/django/template/base.py", line 167, in _render
    return self.nodelist.render(context)
  File "/usr/local/lib/python3.10/site-packages/django/template/base.py", line 1005, in render
    return SafeString("".join([node.render_annotated(context) for node in self]))
  File "/usr/local/lib/python3.10/site-packages/django/template/base.py", line 1005, in <listcomp>
    return SafeString("".join([node.render_annotated(context) for node in self]))
  File "/usr/local/lib/python3.10/site-packages/django/template/base.py", line 966, in render_annotated
    return self.render(context)
  File "/usr/local/lib/python3.10/site-packages/django/template/loader_tags.py", line 157, in render
    return compiled_parent._render(context)
  File "/usr/local/lib/python3.10/site-packages/django/template/base.py", line 167, in _render
    return self.nodelist.render(context)
  File "/usr/local/lib/python3.10/site-packages/django/template/base.py", line 1005, in render
    return SafeString("".join([node.render_annotated(context) for node in self]))
  File "/usr/local/lib/python3.10/site-packages/django/template/base.py", line 1005, in <listcomp>
    return SafeString("".join([node.render_annotated(context) for node in self]))
  File "/usr/local/lib/python3.10/site-packages/django/template/base.py", line 966, in render_annotated
    return self.render(context)
  File "/usr/local/lib/python3.10/site-packages/django/template/loader_tags.py", line 63, in render
    result = block.nodelist.render(context)
  File "/usr/local/lib/python3.10/site-packages/django/template/base.py", line 1005, in render
    return SafeString("".join([node.render_annotated(context) for node in self]))
  File "/usr/local/lib/python3.10/site-packages/django/template/base.py", line 1005, in <listcomp>
    return SafeString("".join([node.render_annotated(context) for node in self]))
  File "/usr/local/lib/python3.10/site-packages/django/template/base.py", line 966, in render_annotated
    return self.render(context)
  File "/usr/local/lib/python3.10/site-packages/django/template/defaulttags.py", line 238, in render
    nodelist.append(node.render_annotated(context))
  File "/usr/local/lib/python3.10/site-packages/django/template/base.py", line 966, in render_annotated
    return self.render(context)
  File "/usr/local/lib/python3.10/site-packages/django/template/defaulttags.py", line 471, in render
    url = reverse(view_name, args=args, kwargs=kwargs, current_app=current_app)
  File "/usr/local/lib/python3.10/site-packages/django/urls/base.py", line 88, in reverse
    return resolver._reverse_with_prefix(view, prefix, *args, **kwargs)
  File "/usr/local/lib/python3.10/site-packages/django/urls/resolvers.py", line 828, in _reverse_with_prefix
    raise NoReverseMatch(msg)
django.urls.exceptions.NoReverseMatch: Reverse for 'product_detail' with arguments '('',)' not found. 1 pattern(s) tried: ['product/(?P<slug>[-a-zA-Z0-9_]+)/\\Z']
ERROR 2025-05-06 21:37:00,489 basehttp "GET / HTTP/1.0" 500 185301
WARNING 2025-05-06 21:38:55,117 log Not Found: /images/placeholder.jpg
WARNING 2025-05-06 21:38:55,122 basehttp "GET /images/placeholder.jpg HTTP/1.0" 404 7242
WARNING 2025-05-06 21:39:15,242 log Not Found: /seller/images/placeholder.jpg
WARNING 2025-05-06 21:39:15,245 basehttp "GET /seller/images/placeholder.jpg HTTP/1.0" 404 7263
ERROR 2025-05-06 21:39:16,705 log Internal Server Error: /seller/products/
Traceback (most recent call last):
  File "/usr/local/lib/python3.10/site-packages/django/core/handlers/exception.py", line 55, in inner
    response = get_response(request)
  File "/usr/local/lib/python3.10/site-packages/django/core/handlers/base.py", line 220, in _get_response
    response = response.render()
  File "/usr/local/lib/python3.10/site-packages/django/template/response.py", line 114, in render
    self.content = self.rendered_content
  File "/usr/local/lib/python3.10/site-packages/django/template/response.py", line 92, in rendered_content
    return template.render(context, self._request)
  File "/usr/local/lib/python3.10/site-packages/django/template/backends/django.py", line 61, in render
    return self.template.render(context)
  File "/usr/local/lib/python3.10/site-packages/django/template/base.py", line 175, in render
    return self._render(context)
  File "/usr/local/lib/python3.10/site-packages/django/template/base.py", line 167, in _render
    return self.nodelist.render(context)
  File "/usr/local/lib/python3.10/site-packages/django/template/base.py", line 1005, in render
    return SafeString("".join([node.render_annotated(context) for node in self]))
  File "/usr/local/lib/python3.10/site-packages/django/template/base.py", line 1005, in <listcomp>
    return SafeString("".join([node.render_annotated(context) for node in self]))
  File "/usr/local/lib/python3.10/site-packages/django/template/base.py", line 966, in render_annotated
    return self.render(context)
  File "/usr/local/lib/python3.10/site-packages/django/template/loader_tags.py", line 157, in render
    return compiled_parent._render(context)
  File "/usr/local/lib/python3.10/site-packages/django/template/base.py", line 167, in _render
    return self.nodelist.render(context)
  File "/usr/local/lib/python3.10/site-packages/django/template/base.py", line 1005, in render
    return SafeString("".join([node.render_annotated(context) for node in self]))
  File "/usr/local/lib/python3.10/site-packages/django/template/base.py", line 1005, in <listcomp>
    return SafeString("".join([node.render_annotated(context) for node in self]))
  File "/usr/local/lib/python3.10/site-packages/django/template/base.py", line 966, in render_annotated
    return self.render(context)
  File "/usr/local/lib/python3.10/site-packages/django/template/loader_tags.py", line 63, in render
    result = block.nodelist.render(context)
  File "/usr/local/lib/python3.10/site-packages/django/template/base.py", line 1005, in render
    return SafeString("".join([node.render_annotated(context) for node in self]))
  File "/usr/local/lib/python3.10/site-packages/django/template/base.py", line 1005, in <listcomp>
    return SafeString("".join([node.render_annotated(context) for node in self]))
  File "/usr/local/lib/python3.10/site-packages/django/template/base.py", line 966, in render_annotated
    return self.render(context)
  File "/usr/local/lib/python3.10/site-packages/django/template/defaulttags.py", line 238, in render
    nodelist.append(node.render_annotated(context))
  File "/usr/local/lib/python3.10/site-packages/django/template/base.py", line 966, in render_annotated
    return self.render(context)
  File "/usr/local/lib/python3.10/site-packages/django/template/defaulttags.py", line 471, in render
    url = reverse(view_name, args=args, kwargs=kwargs, current_app=current_app)
  File "/usr/local/lib/python3.10/site-packages/django/urls/base.py", line 88, in reverse
    return resolver._reverse_with_prefix(view, prefix, *args, **kwargs)
  File "/usr/local/lib/python3.10/site-packages/django/urls/resolvers.py", line 828, in _reverse_with_prefix
    raise NoReverseMatch(msg)
django.urls.exceptions.NoReverseMatch: Reverse for 'product_detail' with arguments '('',)' not found. 1 pattern(s) tried: ['product/(?P<slug>[-a-zA-Z0-9_]+)/\\Z']
ERROR 2025-05-06 21:39:16,713 basehttp "GET /seller/products/ HTTP/1.0" 500 200685
WARNING 2025-05-06 21:44:48,776 log Not Found: /.well-known/appspecific/com.chrome.devtools.json
WARNING 2025-05-06 21:44:48,777 basehttp "GET /.well-known/appspecific/com.chrome.devtools.json HTTP/1.0" 404 7320
ERROR 2025-05-06 21:55:43,477 log Internal Server Error: /products/
Traceback (most recent call last):
  File "/usr/local/lib/python3.10/site-packages/django/core/handlers/exception.py", line 55, in inner
    response = get_response(request)
  File "/usr/local/lib/python3.10/site-packages/django/core/handlers/base.py", line 197, in _get_response
    response = wrapped_callback(request, *callback_args, **callback_kwargs)
  File "/app/apps/products/views.py", line 80, in product_list
    return render(request, 'products/product_list.html', context)
  File "/usr/local/lib/python3.10/site-packages/django/shortcuts.py", line 24, in render
    content = loader.render_to_string(template_name, context, request, using=using)
  File "/usr/local/lib/python3.10/site-packages/django/template/loader.py", line 62, in render_to_string
    return template.render(context, request)
  File "/usr/local/lib/python3.10/site-packages/django/template/backends/django.py", line 61, in render
    return self.template.render(context)
  File "/usr/local/lib/python3.10/site-packages/django/template/base.py", line 175, in render
    return self._render(context)
  File "/usr/local/lib/python3.10/site-packages/django/template/base.py", line 167, in _render
    return self.nodelist.render(context)
  File "/usr/local/lib/python3.10/site-packages/django/template/base.py", line 1005, in render
    return SafeString("".join([node.render_annotated(context) for node in self]))
  File "/usr/local/lib/python3.10/site-packages/django/template/base.py", line 1005, in <listcomp>
    return SafeString("".join([node.render_annotated(context) for node in self]))
  File "/usr/local/lib/python3.10/site-packages/django/template/base.py", line 966, in render_annotated
    return self.render(context)
  File "/usr/local/lib/python3.10/site-packages/django/template/loader_tags.py", line 157, in render
    return compiled_parent._render(context)
  File "/usr/local/lib/python3.10/site-packages/django/template/base.py", line 167, in _render
    return self.nodelist.render(context)
  File "/usr/local/lib/python3.10/site-packages/django/template/base.py", line 1005, in render
    return SafeString("".join([node.render_annotated(context) for node in self]))
  File "/usr/local/lib/python3.10/site-packages/django/template/base.py", line 1005, in <listcomp>
    return SafeString("".join([node.render_annotated(context) for node in self]))
  File "/usr/local/lib/python3.10/site-packages/django/template/base.py", line 966, in render_annotated
    return self.render(context)
  File "/usr/local/lib/python3.10/site-packages/django/template/loader_tags.py", line 63, in render
    result = block.nodelist.render(context)
  File "/usr/local/lib/python3.10/site-packages/django/template/base.py", line 1005, in render
    return SafeString("".join([node.render_annotated(context) for node in self]))
  File "/usr/local/lib/python3.10/site-packages/django/template/base.py", line 1005, in <listcomp>
    return SafeString("".join([node.render_annotated(context) for node in self]))
  File "/usr/local/lib/python3.10/site-packages/django/template/base.py", line 966, in render_annotated
    return self.render(context)
  File "/usr/local/lib/python3.10/site-packages/django/template/defaulttags.py", line 238, in render
    nodelist.append(node.render_annotated(context))
  File "/usr/local/lib/python3.10/site-packages/django/template/base.py", line 966, in render_annotated
    return self.render(context)
  File "/usr/local/lib/python3.10/site-packages/django/template/defaulttags.py", line 471, in render
    url = reverse(view_name, args=args, kwargs=kwargs, current_app=current_app)
  File "/usr/local/lib/python3.10/site-packages/django/urls/base.py", line 88, in reverse
    return resolver._reverse_with_prefix(view, prefix, *args, **kwargs)
  File "/usr/local/lib/python3.10/site-packages/django/urls/resolvers.py", line 828, in _reverse_with_prefix
    raise NoReverseMatch(msg)
django.urls.exceptions.NoReverseMatch: Reverse for 'product_detail' with arguments '('',)' not found. 1 pattern(s) tried: ['product/(?P<slug>[-a-zA-Z0-9_]+)/\\Z']
ERROR 2025-05-06 21:55:43,506 basehttp "GET /products/ HTTP/1.0" 500 204081
ERROR 2025-05-06 21:56:06,844 log Internal Server Error: /products/
Traceback (most recent call last):
  File "/usr/local/lib/python3.10/site-packages/django/core/handlers/exception.py", line 55, in inner
    response = get_response(request)
  File "/usr/local/lib/python3.10/site-packages/django/core/handlers/base.py", line 197, in _get_response
    response = wrapped_callback(request, *callback_args, **callback_kwargs)
  File "/app/apps/products/views.py", line 80, in product_list
    return render(request, 'products/product_list.html', context)
  File "/usr/local/lib/python3.10/site-packages/django/shortcuts.py", line 24, in render
    content = loader.render_to_string(template_name, context, request, using=using)
  File "/usr/local/lib/python3.10/site-packages/django/template/loader.py", line 62, in render_to_string
    return template.render(context, request)
  File "/usr/local/lib/python3.10/site-packages/django/template/backends/django.py", line 61, in render
    return self.template.render(context)
  File "/usr/local/lib/python3.10/site-packages/django/template/base.py", line 175, in render
    return self._render(context)
  File "/usr/local/lib/python3.10/site-packages/django/template/base.py", line 167, in _render
    return self.nodelist.render(context)
  File "/usr/local/lib/python3.10/site-packages/django/template/base.py", line 1005, in render
    return SafeString("".join([node.render_annotated(context) for node in self]))
  File "/usr/local/lib/python3.10/site-packages/django/template/base.py", line 1005, in <listcomp>
    return SafeString("".join([node.render_annotated(context) for node in self]))
  File "/usr/local/lib/python3.10/site-packages/django/template/base.py", line 966, in render_annotated
    return self.render(context)
  File "/usr/local/lib/python3.10/site-packages/django/template/loader_tags.py", line 157, in render
    return compiled_parent._render(context)
  File "/usr/local/lib/python3.10/site-packages/django/template/base.py", line 167, in _render
    return self.nodelist.render(context)
  File "/usr/local/lib/python3.10/site-packages/django/template/base.py", line 1005, in render
    return SafeString("".join([node.render_annotated(context) for node in self]))
  File "/usr/local/lib/python3.10/site-packages/django/template/base.py", line 1005, in <listcomp>
    return SafeString("".join([node.render_annotated(context) for node in self]))
  File "/usr/local/lib/python3.10/site-packages/django/template/base.py", line 966, in render_annotated
    return self.render(context)
  File "/usr/local/lib/python3.10/site-packages/django/template/loader_tags.py", line 63, in render
    result = block.nodelist.render(context)
  File "/usr/local/lib/python3.10/site-packages/django/template/base.py", line 1005, in render
    return SafeString("".join([node.render_annotated(context) for node in self]))
  File "/usr/local/lib/python3.10/site-packages/django/template/base.py", line 1005, in <listcomp>
    return SafeString("".join([node.render_annotated(context) for node in self]))
  File "/usr/local/lib/python3.10/site-packages/django/template/base.py", line 966, in render_annotated
    return self.render(context)
  File "/usr/local/lib/python3.10/site-packages/django/template/defaulttags.py", line 238, in render
    nodelist.append(node.render_annotated(context))
  File "/usr/local/lib/python3.10/site-packages/django/template/base.py", line 966, in render_annotated
    return self.render(context)
  File "/usr/local/lib/python3.10/site-packages/django/template/defaulttags.py", line 471, in render
    url = reverse(view_name, args=args, kwargs=kwargs, current_app=current_app)
  File "/usr/local/lib/python3.10/site-packages/django/urls/base.py", line 88, in reverse
    return resolver._reverse_with_prefix(view, prefix, *args, **kwargs)
  File "/usr/local/lib/python3.10/site-packages/django/urls/resolvers.py", line 828, in _reverse_with_prefix
    raise NoReverseMatch(msg)
django.urls.exceptions.NoReverseMatch: Reverse for 'product_detail' with arguments '('',)' not found. 1 pattern(s) tried: ['product/(?P<slug>[-a-zA-Z0-9_]+)/\\Z']
ERROR 2025-05-06 21:56:06,877 basehttp "GET /products/ HTTP/1.0" 500 204081
ERROR 2025-05-06 21:59:08,476 log Internal Server Error: /add-to-wishlist/
Traceback (most recent call last):
  File "/usr/local/lib/python3.10/site-packages/django/core/handlers/exception.py", line 55, in inner
    response = get_response(request)
  File "/usr/local/lib/python3.10/site-packages/django/core/handlers/base.py", line 197, in _get_response
    response = wrapped_callback(request, *callback_args, **callback_kwargs)
  File "/usr/local/lib/python3.10/site-packages/django/contrib/auth/decorators.py", line 23, in _wrapper_view
    return view_func(request, *args, **kwargs)
  File "/usr/local/lib/python3.10/site-packages/django/views/decorators/http.py", line 43, in inner
    return func(request, *args, **kwargs)
  File "/app/apps/products/views.py", line 225, in add_to_wishlist
    if request.is_ajax():
AttributeError: 'WSGIRequest' object has no attribute 'is_ajax'
ERROR 2025-05-06 21:59:08,483 basehttp "POST /add-to-wishlist/ HTTP/1.0" 500 74168
ERROR 2025-05-06 21:59:10,126 log Internal Server Error: /add-to-wishlist/
Traceback (most recent call last):
  File "/usr/local/lib/python3.10/site-packages/django/core/handlers/exception.py", line 55, in inner
    response = get_response(request)
  File "/usr/local/lib/python3.10/site-packages/django/core/handlers/base.py", line 197, in _get_response
    response = wrapped_callback(request, *callback_args, **callback_kwargs)
  File "/usr/local/lib/python3.10/site-packages/django/contrib/auth/decorators.py", line 23, in _wrapper_view
    return view_func(request, *args, **kwargs)
  File "/usr/local/lib/python3.10/site-packages/django/views/decorators/http.py", line 43, in inner
    return func(request, *args, **kwargs)
  File "/app/apps/products/views.py", line 225, in add_to_wishlist
    if request.is_ajax():
AttributeError: 'WSGIRequest' object has no attribute 'is_ajax'
ERROR 2025-05-06 21:59:10,134 basehttp "POST /add-to-wishlist/ HTTP/1.0" 500 74167
ERROR 2025-05-06 21:59:10,318 log Internal Server Error: /add-to-wishlist/
Traceback (most recent call last):
  File "/usr/local/lib/python3.10/site-packages/django/core/handlers/exception.py", line 55, in inner
    response = get_response(request)
  File "/usr/local/lib/python3.10/site-packages/django/core/handlers/base.py", line 197, in _get_response
    response = wrapped_callback(request, *callback_args, **callback_kwargs)
  File "/usr/local/lib/python3.10/site-packages/django/contrib/auth/decorators.py", line 23, in _wrapper_view
    return view_func(request, *args, **kwargs)
  File "/usr/local/lib/python3.10/site-packages/django/views/decorators/http.py", line 43, in inner
    return func(request, *args, **kwargs)
  File "/app/apps/products/views.py", line 225, in add_to_wishlist
    if request.is_ajax():
AttributeError: 'WSGIRequest' object has no attribute 'is_ajax'
ERROR 2025-05-06 21:59:10,324 basehttp "POST /add-to-wishlist/ HTTP/1.0" 500 74168
ERROR 2025-05-06 21:59:11,678 log Internal Server Error: /wishlist/
Traceback (most recent call last):
  File "/usr/local/lib/python3.10/site-packages/django/core/handlers/exception.py", line 55, in inner
    response = get_response(request)
  File "/usr/local/lib/python3.10/site-packages/django/core/handlers/base.py", line 197, in _get_response
    response = wrapped_callback(request, *callback_args, **callback_kwargs)
  File "/usr/local/lib/python3.10/site-packages/django/contrib/auth/decorators.py", line 23, in _wrapper_view
    return view_func(request, *args, **kwargs)
  File "/app/apps/products/views.py", line 239, in wishlist
    return render(request, 'products/wishlist.html', context)
  File "/usr/local/lib/python3.10/site-packages/django/shortcuts.py", line 24, in render
    content = loader.render_to_string(template_name, context, request, using=using)
  File "/usr/local/lib/python3.10/site-packages/django/template/loader.py", line 62, in render_to_string
    return template.render(context, request)
  File "/usr/local/lib/python3.10/site-packages/django/template/backends/django.py", line 61, in render
    return self.template.render(context)
  File "/usr/local/lib/python3.10/site-packages/django/template/base.py", line 175, in render
    return self._render(context)
  File "/usr/local/lib/python3.10/site-packages/django/template/base.py", line 167, in _render
    return self.nodelist.render(context)
  File "/usr/local/lib/python3.10/site-packages/django/template/base.py", line 1005, in render
    return SafeString("".join([node.render_annotated(context) for node in self]))
  File "/usr/local/lib/python3.10/site-packages/django/template/base.py", line 1005, in <listcomp>
    return SafeString("".join([node.render_annotated(context) for node in self]))
  File "/usr/local/lib/python3.10/site-packages/django/template/base.py", line 966, in render_annotated
    return self.render(context)
  File "/usr/local/lib/python3.10/site-packages/django/template/loader_tags.py", line 157, in render
    return compiled_parent._render(context)
  File "/usr/local/lib/python3.10/site-packages/django/template/base.py", line 167, in _render
    return self.nodelist.render(context)
  File "/usr/local/lib/python3.10/site-packages/django/template/base.py", line 1005, in render
    return SafeString("".join([node.render_annotated(context) for node in self]))
  File "/usr/local/lib/python3.10/site-packages/django/template/base.py", line 1005, in <listcomp>
    return SafeString("".join([node.render_annotated(context) for node in self]))
  File "/usr/local/lib/python3.10/site-packages/django/template/base.py", line 966, in render_annotated
    return self.render(context)
  File "/usr/local/lib/python3.10/site-packages/django/template/loader_tags.py", line 63, in render
    result = block.nodelist.render(context)
  File "/usr/local/lib/python3.10/site-packages/django/template/base.py", line 1005, in render
    return SafeString("".join([node.render_annotated(context) for node in self]))
  File "/usr/local/lib/python3.10/site-packages/django/template/base.py", line 1005, in <listcomp>
    return SafeString("".join([node.render_annotated(context) for node in self]))
  File "/usr/local/lib/python3.10/site-packages/django/template/base.py", line 966, in render_annotated
    return self.render(context)
  File "/usr/local/lib/python3.10/site-packages/django/template/defaulttags.py", line 321, in render
    return nodelist.render(context)
  File "/usr/local/lib/python3.10/site-packages/django/template/base.py", line 1005, in render
    return SafeString("".join([node.render_annotated(context) for node in self]))
  File "/usr/local/lib/python3.10/site-packages/django/template/base.py", line 1005, in <listcomp>
    return SafeString("".join([node.render_annotated(context) for node in self]))
  File "/usr/local/lib/python3.10/site-packages/django/template/base.py", line 966, in render_annotated
    return self.render(context)
  File "/usr/local/lib/python3.10/site-packages/django/template/defaulttags.py", line 238, in render
    nodelist.append(node.render_annotated(context))
  File "/usr/local/lib/python3.10/site-packages/django/template/base.py", line 966, in render_annotated
    return self.render(context)
  File "/usr/local/lib/python3.10/site-packages/django/template/defaulttags.py", line 471, in render
    url = reverse(view_name, args=args, kwargs=kwargs, current_app=current_app)
  File "/usr/local/lib/python3.10/site-packages/django/urls/base.py", line 88, in reverse
    return resolver._reverse_with_prefix(view, prefix, *args, **kwargs)
  File "/usr/local/lib/python3.10/site-packages/django/urls/resolvers.py", line 828, in _reverse_with_prefix
    raise NoReverseMatch(msg)
django.urls.exceptions.NoReverseMatch: Reverse for 'product_detail' with arguments '('',)' not found. 1 pattern(s) tried: ['product/(?P<slug>[-a-zA-Z0-9_]+)/\\Z']
ERROR 2025-05-06 21:59:11,687 basehttp "GET /wishlist/ HTTP/1.0" 500 204123
ERROR 2025-05-06 21:59:19,114 log Internal Server Error: /wishlist/
Traceback (most recent call last):
  File "/usr/local/lib/python3.10/site-packages/django/core/handlers/exception.py", line 55, in inner
    response = get_response(request)
  File "/usr/local/lib/python3.10/site-packages/django/core/handlers/base.py", line 197, in _get_response
    response = wrapped_callback(request, *callback_args, **callback_kwargs)
  File "/usr/local/lib/python3.10/site-packages/django/contrib/auth/decorators.py", line 23, in _wrapper_view
    return view_func(request, *args, **kwargs)
  File "/app/apps/products/views.py", line 239, in wishlist
    return render(request, 'products/wishlist.html', context)
  File "/usr/local/lib/python3.10/site-packages/django/shortcuts.py", line 24, in render
    content = loader.render_to_string(template_name, context, request, using=using)
  File "/usr/local/lib/python3.10/site-packages/django/template/loader.py", line 62, in render_to_string
    return template.render(context, request)
  File "/usr/local/lib/python3.10/site-packages/django/template/backends/django.py", line 61, in render
    return self.template.render(context)
  File "/usr/local/lib/python3.10/site-packages/django/template/base.py", line 175, in render
    return self._render(context)
  File "/usr/local/lib/python3.10/site-packages/django/template/base.py", line 167, in _render
    return self.nodelist.render(context)
  File "/usr/local/lib/python3.10/site-packages/django/template/base.py", line 1005, in render
    return SafeString("".join([node.render_annotated(context) for node in self]))
  File "/usr/local/lib/python3.10/site-packages/django/template/base.py", line 1005, in <listcomp>
    return SafeString("".join([node.render_annotated(context) for node in self]))
  File "/usr/local/lib/python3.10/site-packages/django/template/base.py", line 966, in render_annotated
    return self.render(context)
  File "/usr/local/lib/python3.10/site-packages/django/template/loader_tags.py", line 157, in render
    return compiled_parent._render(context)
  File "/usr/local/lib/python3.10/site-packages/django/template/base.py", line 167, in _render
    return self.nodelist.render(context)
  File "/usr/local/lib/python3.10/site-packages/django/template/base.py", line 1005, in render
    return SafeString("".join([node.render_annotated(context) for node in self]))
  File "/usr/local/lib/python3.10/site-packages/django/template/base.py", line 1005, in <listcomp>
    return SafeString("".join([node.render_annotated(context) for node in self]))
  File "/usr/local/lib/python3.10/site-packages/django/template/base.py", line 966, in render_annotated
    return self.render(context)
  File "/usr/local/lib/python3.10/site-packages/django/template/loader_tags.py", line 63, in render
    result = block.nodelist.render(context)
  File "/usr/local/lib/python3.10/site-packages/django/template/base.py", line 1005, in render
    return SafeString("".join([node.render_annotated(context) for node in self]))
  File "/usr/local/lib/python3.10/site-packages/django/template/base.py", line 1005, in <listcomp>
    return SafeString("".join([node.render_annotated(context) for node in self]))
  File "/usr/local/lib/python3.10/site-packages/django/template/base.py", line 966, in render_annotated
    return self.render(context)
  File "/usr/local/lib/python3.10/site-packages/django/template/defaulttags.py", line 321, in render
    return nodelist.render(context)
  File "/usr/local/lib/python3.10/site-packages/django/template/base.py", line 1005, in render
    return SafeString("".join([node.render_annotated(context) for node in self]))
  File "/usr/local/lib/python3.10/site-packages/django/template/base.py", line 1005, in <listcomp>
    return SafeString("".join([node.render_annotated(context) for node in self]))
  File "/usr/local/lib/python3.10/site-packages/django/template/base.py", line 966, in render_annotated
    return self.render(context)
  File "/usr/local/lib/python3.10/site-packages/django/template/defaulttags.py", line 238, in render
    nodelist.append(node.render_annotated(context))
  File "/usr/local/lib/python3.10/site-packages/django/template/base.py", line 966, in render_annotated
    return self.render(context)
  File "/usr/local/lib/python3.10/site-packages/django/template/defaulttags.py", line 471, in render
    url = reverse(view_name, args=args, kwargs=kwargs, current_app=current_app)
  File "/usr/local/lib/python3.10/site-packages/django/urls/base.py", line 88, in reverse
    return resolver._reverse_with_prefix(view, prefix, *args, **kwargs)
  File "/usr/local/lib/python3.10/site-packages/django/urls/resolvers.py", line 828, in _reverse_with_prefix
    raise NoReverseMatch(msg)
django.urls.exceptions.NoReverseMatch: Reverse for 'product_detail' with arguments '('',)' not found. 1 pattern(s) tried: ['product/(?P<slug>[-a-zA-Z0-9_]+)/\\Z']
ERROR 2025-05-06 21:59:19,124 basehttp "GET /wishlist/ HTTP/1.0" 500 204108
ERROR 2025-05-06 22:01:43,801 log Internal Server Error: /add-to-wishlist/
Traceback (most recent call last):
  File "/usr/local/lib/python3.10/site-packages/django/core/handlers/exception.py", line 55, in inner
    response = get_response(request)
  File "/usr/local/lib/python3.10/site-packages/django/core/handlers/base.py", line 197, in _get_response
    response = wrapped_callback(request, *callback_args, **callback_kwargs)
  File "/usr/local/lib/python3.10/site-packages/django/contrib/auth/decorators.py", line 23, in _wrapper_view
    return view_func(request, *args, **kwargs)
  File "/usr/local/lib/python3.10/site-packages/django/views/decorators/http.py", line 43, in inner
    return func(request, *args, **kwargs)
  File "/app/apps/products/views.py", line 225, in add_to_wishlist
    if request.is_ajax():
AttributeError: 'WSGIRequest' object has no attribute 'is_ajax'
ERROR 2025-05-06 22:01:43,808 basehttp "POST /add-to-wishlist/ HTTP/1.0" 500 74152
ERROR 2025-05-06 22:01:47,634 log Internal Server Error: /add-to-wishlist/
Traceback (most recent call last):
  File "/usr/local/lib/python3.10/site-packages/django/core/handlers/exception.py", line 55, in inner
    response = get_response(request)
  File "/usr/local/lib/python3.10/site-packages/django/core/handlers/base.py", line 197, in _get_response
    response = wrapped_callback(request, *callback_args, **callback_kwargs)
  File "/usr/local/lib/python3.10/site-packages/django/contrib/auth/decorators.py", line 23, in _wrapper_view
    return view_func(request, *args, **kwargs)
  File "/usr/local/lib/python3.10/site-packages/django/views/decorators/http.py", line 43, in inner
    return func(request, *args, **kwargs)
  File "/app/apps/products/views.py", line 225, in add_to_wishlist
    if request.is_ajax():
AttributeError: 'WSGIRequest' object has no attribute 'is_ajax'
ERROR 2025-05-06 22:01:47,640 basehttp "POST /add-to-wishlist/ HTTP/1.0" 500 74153
ERROR 2025-05-06 22:01:55,137 log Internal Server Error: /add-to-wishlist/
Traceback (most recent call last):
  File "/usr/local/lib/python3.10/site-packages/django/core/handlers/exception.py", line 55, in inner
    response = get_response(request)
  File "/usr/local/lib/python3.10/site-packages/django/core/handlers/base.py", line 197, in _get_response
    response = wrapped_callback(request, *callback_args, **callback_kwargs)
  File "/usr/local/lib/python3.10/site-packages/django/contrib/auth/decorators.py", line 23, in _wrapper_view
    return view_func(request, *args, **kwargs)
  File "/usr/local/lib/python3.10/site-packages/django/views/decorators/http.py", line 43, in inner
    return func(request, *args, **kwargs)
  File "/app/apps/products/views.py", line 225, in add_to_wishlist
    if request.is_ajax():
AttributeError: 'WSGIRequest' object has no attribute 'is_ajax'
ERROR 2025-05-06 22:01:55,145 basehttp "POST /add-to-wishlist/ HTTP/1.0" 500 74152
ERROR 2025-05-06 22:05:20,861 log Internal Server Error: /add-to-wishlist/
Traceback (most recent call last):
  File "/usr/local/lib/python3.10/site-packages/django/core/handlers/exception.py", line 55, in inner
    response = get_response(request)
  File "/usr/local/lib/python3.10/site-packages/django/core/handlers/base.py", line 197, in _get_response
    response = wrapped_callback(request, *callback_args, **callback_kwargs)
  File "/usr/local/lib/python3.10/site-packages/django/contrib/auth/decorators.py", line 23, in _wrapper_view
    return view_func(request, *args, **kwargs)
  File "/usr/local/lib/python3.10/site-packages/django/views/decorators/http.py", line 43, in inner
    return func(request, *args, **kwargs)
  File "/app/apps/products/views.py", line 225, in add_to_wishlist
    if request.is_ajax():
AttributeError: 'WSGIRequest' object has no attribute 'is_ajax'
ERROR 2025-05-06 22:05:20,868 basehttp "POST /add-to-wishlist/ HTTP/1.0" 500 74153
ERROR 2025-05-06 22:06:40,458 log Internal Server Error: /product/id/2/
Traceback (most recent call last):
  File "/usr/local/lib/python3.10/site-packages/django/core/handlers/exception.py", line 55, in inner
    response = get_response(request)
  File "/usr/local/lib/python3.10/site-packages/django/core/handlers/base.py", line 197, in _get_response
    response = wrapped_callback(request, *callback_args, **callback_kwargs)
  File "/app/apps/products/views.py", line 210, in product_detail_by_id
    return redirect('product_detail', slug=product.slug)
  File "/usr/local/lib/python3.10/site-packages/django/shortcuts.py", line 48, in redirect
    return redirect_class(resolve_url(to, *args, **kwargs))
  File "/usr/local/lib/python3.10/site-packages/django/shortcuts.py", line 145, in resolve_url
    return reverse(to, args=args, kwargs=kwargs)
  File "/usr/local/lib/python3.10/site-packages/django/urls/base.py", line 88, in reverse
    return resolver._reverse_with_prefix(view, prefix, *args, **kwargs)
  File "/usr/local/lib/python3.10/site-packages/django/urls/resolvers.py", line 828, in _reverse_with_prefix
    raise NoReverseMatch(msg)
django.urls.exceptions.NoReverseMatch: Reverse for 'product_detail' not found. 'product_detail' is not a valid view function or pattern name.
ERROR 2025-05-06 22:06:40,469 basehttp "GET /product/id/2/ HTTP/1.0" 500 82503
WARNING 2025-05-06 22:07:42,800 log Not Found: /product//
WARNING 2025-05-06 22:07:42,802 basehttp "GET /product// HTTP/1.0" 404 7217
WARNING 2025-05-06 22:07:49,753 log Not Found: /product//
WARNING 2025-05-06 22:07:49,754 basehttp "GET /product// HTTP/1.0" 404 7217
